<?xml version="1.0" encoding="utf-8"?>
<!-- This URDF was automatically created by SolidWorks to URDF Exporter! Originally created by Stephen Brawner (brawner@gmail.com) 
     Commit Version: 1.6.0-1-g15f4949  Build Version: 1.6.7594.29634
     For more information, please see http://wiki.ros.org/sw_urdf_exporter -->
<robot
  name="itu_odv_description">
  <!-- base_link -->
  <link
    name="base_link">
    <inertial>
      <origin
        xyz="3.1086E-15 3.1114E-14 0.063778"
        rpy="0 0 0" />
      <mass
        value="1" />
      <inertia
        ixx="0.0838"
        ixy="2.8145E-10"
        ixz="-9.7612E-15"
        iyy="0.079577"
        iyz="-3.0801E-17"
        izz="0.15789" />
    </inertial>
    <visual>
      <origin
        xyz="0 0 0"
        rpy="0 0 0" />
      <geometry>
        <mesh
          filename="package://itu_odv_description/meshes/base_link.STL" />
      </geometry>
      <material
        name="">
        <color
          rgba="0.79216 0.81961 0.93333 1" />
      </material>
    </visual>
    <collision>
      <origin
        xyz="0 0 0"
        rpy="0 0 0" />
      <geometry>
        <mesh
          filename="package://itu_odv_description/meshes/base_link.STL" />
      </geometry>
    </collision>
  </link>
  <!-- front_right_wheel_link -->
  <link
    name="front_right_wheel_link">
    <inertial>
      <origin
        xyz="-5.2003E-09 -1.5816E-05 -7.4067E-09"
        rpy="0 0 0" />
      <mass
        value="0.1" />
      <inertia
        ixx="0.00072883"
        ixy="2.5798E-11"
        ixz="-2.3168E-10"
        iyy="0.0013926"
        iyz="-3.7292E-11"
        izz="0.00072883" />
    </inertial>
    <visual>
      <origin
        xyz="0 0 0"
        rpy="0 0 0" />
      <geometry>
        <mesh
          filename="package://itu_odv_description/meshes/front_right_wheel_link.STL" />
      </geometry>
      <material
        name="">
        <color
          rgba="0.79216 0.81961 0.93333 1" />
      </material>
    </visual>
    <collision>
      <origin
        xyz="-5.2003E-09 -1.5816E-05 -7.4067E-09"
        rpy="0 0 0" />
      <geometry>
        <mesh
          filename="package://itu_odv_description/meshes/front_right_wheel_link.STL" />
      </geometry>
    </collision>
  </link>
  <joint
    name="front_right_wheel_joint"
    type="continuous">
    <origin
      xyz="0.265 -0.275 -0.0053038"
      rpy="0 0 0" />
    <parent
      link="base_link" />
    <child
      link="front_right_wheel_link" />
    <axis
      xyz="0 1 0" />
    <limit
      effort="100"
      velocity="100" />
  </joint>

  <!-- front_left_wheel_link -->
  <link
    name="front_left_wheel_link">
    <inertial>
      <origin
        xyz="-1.2223E-09 1.599E-05 1.0161E-08"
        rpy="0 0 0" />
      <mass
        value="0.1" />
      <inertia
        ixx="0.00072883"
        ixy="4.9301E-13"
        ixz="-1.1558E-10"
        iyy="0.0013926"
        iyz="-2.5587E-11"
        izz="0.00072883" />
    </inertial>
    <visual>
      <origin
        xyz="0 0 0"
        rpy="0 0 0" />
      <geometry>
        <mesh
          filename="package://itu_odv_description/meshes/front_left_wheel_link.STL" />
      </geometry>
      <material
        name="">
        <color
          rgba="0.67843 0.67843 0.72941 1" />
      </material>
    </visual>
    <collision>
      <origin
        xyz="-5.2003E-09 -1.5816E-05 -7.4067E-09"
        rpy="0 0 0" />
      <geometry>
        <mesh
          filename="package://itu_odv_description/meshes/front_left_wheel_link.STL" />
      </geometry>
    </collision>
  </link>
  <joint
    name="front_left_wheel_joint"
    type="continuous">
    <origin
      xyz="0.265 0.275 -0.0053038"
      rpy="0 0 0" />
    <parent
      link="base_link" />
    <child
      link="front_left_wheel_link" />
    <axis
      xyz="0 -1 0" />
    <limit
      effort="100"
      velocity="100" />
  </joint>

  <!-- rear_right_wheel_link -->
  <link
    name="rear_right_wheel_link">
    <inertial>
      <origin
        xyz="9.4049E-12 1.599E-05 9.4543E-09"
        rpy="0 0 0" />
      <mass
        value="0.1" />
      <inertia
        ixx="0.00072883"
        ixy="2.1862E-12"
        ixz="-3.7811E-10"
        iyy="0.0013926"
        iyz="-1.9384E-11"
        izz="0.00072883" />
    </inertial>
    <visual>
      <origin
        xyz="0 0 0"
        rpy="0 0 0" />
      <geometry>
        <mesh
          filename="package://itu_odv_description/meshes/rear_right_wheel_link.STL" />
      </geometry>
      <material
        name="">
        <color
          rgba="0.67843 0.67843 0.72941 1" />
      </material>
    </visual>
    <collision>
      <origin
        xyz="-5.2003E-09 -1.5816E-05 -7.4067E-09"
        rpy="0 0 0" />
      <geometry>
        <mesh
          filename="package://itu_odv_description/meshes/rear_right_wheel_link.STL" />
      </geometry>
    </collision>
  </link>
  <joint
    name="rear_right_wheel_joint"
    type="continuous">
    <origin
      xyz="-0.265 -0.275 -0.0053038"
      rpy="0 0 0" />
    <parent
      link="base_link" />
    <child
      link="rear_right_wheel_link" />
    <axis
      xyz="0 1 0" />
    <limit
      effort="100"
      velocity="100" />
  </joint>

  <!-- rear_left_wheel_link -->
  <link
    name="rear_left_wheel_link">
    <inertial>
      <origin
        xyz="-5.1274E-09 -1.5816E-05 -7.7023E-09"
        rpy="0 0 0" />
      <mass
        value="0.1" />
      <inertia
        ixx="0.00072883"
        ixy="3.1087E-11"
        ixz="-2.0848E-10"
        iyy="0.0013926"
        iyz="-3.4598E-11"
        izz="0.00072883" />
    </inertial>
    <visual>
      <origin
        xyz="0 0 0"
        rpy="0 0 0" />
      <geometry>
        <mesh
          filename="package://itu_odv_description/meshes/rear_left_wheel_link.STL" />
      </geometry>
      <material
        name="">
        <color
          rgba="0.79216 0.81961 0.93333 1" />
      </material>
    </visual>
    <collision>
      <origin
        xyz="-5.2003E-09 -1.5816E-05 -7.4067E-09"
        rpy="0 0 0" />
      <geometry>
        <mesh
          filename="package://itu_odv_description/meshes/rear_left_wheel_link.STL" />
      </geometry>
    </collision>
  </link>
  <joint
    name="rear_left_wheel_joint"
    type="continuous">
    <origin
      xyz="-0.265 0.275 -0.0053038"
      rpy="0 0 0" />
    <parent
      link="base_link" />
    <child
      link="rear_left_wheel_link" />
    <axis
      xyz="0 -1 0" />
    <limit
      effort="100"
      velocity="100" />
  </joint>

  <!-- front_laser -->
  <link
    name="front_laser_link">
    <inertial>
      <origin
        xyz="0 0 0"
        rpy="0 0 0" />
      <mass
        value="0.1" />
      <inertia
        ixx="0"
        ixy="0"
        ixz="0"
        iyy="0"
        iyz="0"
        izz="0" />
    </inertial>
    <visual>
      <origin
        xyz="0 0 0"
        rpy="0 0 0" />
      <geometry>
        <mesh
          filename="package://itu_odv_description/meshes/front_laser_link.STL" />
      </geometry>
      <material
        name="">
        <color
          rgba="1 1 1 1" />
      </material>
    </visual>
    <collision>
      <origin
        xyz="0 0 0"
        rpy="0 0 0" />
      <geometry>
        <mesh
          filename="package://itu_odv_description/meshes/front_laser_link.STL" />
      </geometry>
    </collision>
  </link>
  <joint
    name="front_laser_joint"
    type="fixed">
    <origin
      xyz="0.25602 -0.21602 0.1487"
      rpy="3.1416 0 -0.7854" />
    <parent
      link="base_link" />
    <child
      link="front_laser_link" />
    <axis
      xyz="0 0 0" />
  </joint>

  <!-- rear_laser -->
  <link
    name="rear_laser_link">
    <inertial>
      <origin
        xyz="0 0 0"
        rpy="0 0 0" />
      <mass
        value="0.1" />
      <inertia
        ixx="0"
        ixy="0"
        ixz="0"
        iyy="0"
        iyz="0"
        izz="0" />
    </inertial>
    <visual>
      <origin
        xyz="0 0 0"
        rpy="0 0 0" />
      <geometry>
        <mesh
          filename="package://itu_odv_description/meshes/rear_laser_link.STL" />
      </geometry>
      <material
        name="">
        <color
          rgba="1 1 1 1" />
      </material>
    </visual>
    <collision>
      <origin
        xyz="0 0 0"
        rpy="0 0 0" />
      <geometry>
        <mesh
          filename="package://itu_odv_description/meshes/rear_laser_link.STL" />
      </geometry>
    </collision>
  </link>
  <joint
    name="rear_laser_joint"
    type="fixed">
    <origin
      xyz="-0.25602 0.21602 0.1487"
      rpy="-3.1416 0 2.3562" />
    <parent
      link="base_link" />
    <child
      link="rear_laser_link" />
    <axis
      xyz="0 0 0" />
  </joint>

  <!-- imu link -->
  <link name="imu_link">
	<inertial>
		<mass value="1e-5" />
		<origin xyz="0 0 0" rpy="0 0 0" />
		<inertia ixx="1e-6" ixy="0" ixz="0" iyy="1e-6" iyz="0" izz="1e-6" />
	</inertial>

	<visual>
		<origin xyz="0 0 0" rpy="0 0 0" />
		<geometry>
			<box size="0.01 0.01 0.01" />
		</geometry>
	</visual>

	<collision>
		<origin xyz="0 0 0" rpy="0 0 0" />
		<geometry>
			<box size="0.01 0.01 0.01" />
		</geometry>
	</collision>
  </link>

  <joint name="imu_joint" type="fixed">
	<axis xyz="0 1 0" />
	<origin xyz="0 0 0.1" rpy="0 0 0" /> 
	<parent link="base_link" />
	<child link="imu_link" />
  </joint>
  
  
</robot>
